Workbook

Sheet DATA
A1: No. | B1: No. Ke Unit Kerja Asal | C1: No. Ke Unit Kerja tujuan | D1: No. Ke Unit Kerja tujuan (jika sekolah) | E1: Tanggal | F1: Bulan | G1: Tahun | H1: ROMAWI | I1: IZIN TENTANG | J1: DASAR SURAT | K1: TANGGAL SURAT | L1: PENANDATANGAN SURAT | M1: HAL SURAT | N1: TUJUAN SURAT | O1: NAMA | P1: NIM/NIS TULIS | Q1: NIM/NIS | R1: JURUSAN/PRODI | S1: TEMPAT PKL | T1: PESERTA DIDIK/MAHASISWA | U1: UNIT KERJA ASAL | V1: AWAL TANGGAL | W1: AKHIR TANGGAL | X1: Tembusan1 | Y1: Tembusan2 | Z1: KETERANGAN | AA1: SERTIFIKAT | AB1: Awal Bulan | AC1: Akhir Bulan | AD1: Thn Awal | AE1: AKHIR | AF1: 1 | AG1: 2 | AH1: 3 | AI1: 4 | AJ1: 5 | AK1: 6 | AL1: 7 | AM1: 8 | AN1: 9 | AO1: 10 | AP1: 11 | AQ1: 12 | AR1: 1 | AS1: 2 | AT1: 3 | AU1: 4 | AV1: 5 | AW1: 6 | AX1: 7 | AY1: 8 | AZ1: 9 | BA1: 10 | BB1: 11 | BC1: 12 | BD1: 1 | BE1: 2 | BF1: 3 | BG1: 4 | BH1: 5 | BI1: 6 | BJ1: 7 | BK1: 8 | BL1: 9 | BM1: 10 | BN1: 11 | BO1: 12
B2: 5430 | D2: 5431 | E2: 6 | F2: Maret | G2: 2026 | H2: =VLOOKUP(F2,MASTER!$B$2:$C$13,2,FALSE) -> III | I2: Pemberian Izin Melakukan Field Project | J2: 0359/UN9.FK/SB2.AF.AF1/2026 | K2: 23 Februari 2026 | L2: Dekan Fakultas Kedokteran Universitas Sriwijaya | M2: Izin Melakukan Field Project | O2: Jasmine Putria Zahara | P2: 04041282328019 | Q2: NIM | R2: Program Studi Psikologi Fakultas Kedokteran Universitas Sriwijaya | S2: SMA Negeri 16 Palembang | T2: =IF(Q2="NIM","Mahasiswa","Peserta Didik") -> Mahasiswa | U2: Universitas Sriwijaya | Z2: SELESAI | AA2: =IF(ISNA(MATCH(O2,SERTIFIKAT!$G$2:$G$237,0)),"","SERTIFIKAT SELESAI") | AB2: =MONTH(V2) -> 1 | AC2: =MONTH(W2) -> 1 | AD2: =YEAR(V2) -> 1900 | AE2: =YEAR(W2) -> 1900 | AF2: =AB2 -> 1 | AG2: =AF2+1 -> 2 | AH2: =AG2+1 -> 3 | AI2: =AH2+1 -> 4 | AJ2: =AI2+1 -> 5 | AK2: =AJ2+1 -> 6 | AL2: =AK2+1 -> 7 | AM2: =AL2+1 -> 8 | AN2: =AM2+1 -> 9 | ... AQ2: =AP2+1 -> 12 | BD2: =S2&AR2&AD2 -> SMA Negeri 16 Palembang1900 | BE2: =S2&AS2&AD2 -> SMA Negeri 16 Palembang1900 | BF2: =S2&AT2&AD2 -> SMA Negeri 16 Palembang1900 | BG2: =S2&AU2&AD2 -> SMA Negeri 16 Palembang1900 | BH2: =S2&AV2&AD2 -> SMA Negeri 16 Palembang1900 | BI2: =S2&AW2&AD2 -> SMA Negeri 16 Palembang1900 | BJ2: =S2&AX2&AD2 -> SMA Negeri 16 Palembang1900 | BK2: =S2&AY2&AD2 -> SMA Negeri 16 Palembang1900 | BL2: =S2&AZ2&AD2 -> SMA Negeri 16 Palembang1900 | BM2: =S2&BA2&AD2 -> SMA Negeri 16 Palembang1900 | BN2: =S2&BB2&AD2 -> SMA Negeri 16 Palembang1900 | BO2: =S2&BC2&AD2 -> SMA Negeri 16 Palembang1900
B3: 5430 | D3: 5431 | E3: 6 | F3: Maret | G3: 2026 | H3: =VLOOKUP(F3,MASTER!$B$2:$C$13,2,FALSE) -> III | I3: Pemberian Izin Melakukan Field Project | J3: 0359/UN9.FK/SB2.AF.AF1/2026 | K3: 23 Februari 2026 | L3: Dekan Fakultas Kedokteran Universitas Sriwijaya | M3: Izin Melakukan Field Project | O3: Alifa Tsabitah | P3: 04041282328023 | Q3: NIM | R3: Program Studi Psikologi Fakultas Kedokteran Universitas Sriwijaya | S3: SMA Negeri 16 Palembang | T3: =IF(Q3="NIM","Mahasiswa","Peserta Didik") -> Mahasiswa | U3: Universitas Sriwijaya | Z3: SELESAI | AA3: =IF(ISNA(MATCH(O3,SERTIFIKAT!$G$2:$G$237,0)),"","SERTIFIKAT SELESAI") | AB3: =MONTH(V3) -> 1 | AC3: =MONTH(W3) -> 1 | AD3: =YEAR(V3) -> 1900 | AE3: =YEAR(W3) -> 1900 | AF3: =AB3 -> 1 | AG3: =AF3+1 -> 2 | AH3: =AG3+1 -> 3 | AI3: =AH3+1 -> 4 | AJ3: =AI3+1 -> 5 | AK3: =AJ3+1 -> 6 | AL3: =AK3+1 -> 7 | AM3: =AL3+1 -> 8 | AN3: =AM3+1 -> 9 | ... AQ3: =AP3+1 -> 12 | AR3: =IF(AF3<AC3+1,AF3,"") -> 1 | AS3: =IF(AG3<AC3+1,AG3,"") | AT3: =IF(AH3<AC3+1,AH3,"") | AU3: =IF(AI3<AC3+1,AI3,"") | AV3: =IF(AJ3<AC3+1,AJ3,"") | AW3: =IF(AK3<AC3+1,AK3,"") | AX3: =IF(AL3<AC3+1,AL3,"") | AY3: =IF(AM3<AC3+1,AM3,"") | AZ3: =IF(AN3<AC3+1,AN3,"") | BA3: =IF(AO3<AC3+1,AO3,"") | BB3: =IF(AP3<AC3+1,AP3,"") | BC3: =IF(AQ3<AC3+1,AQ3,"") | BD3: =S3&AR3&AD3 -> SMA Negeri 16 Palembang11900 | BE3: =S3&AS3&AD3 -> SMA Negeri 16 Palembang1900 | BF3: =S3&AT3&AD3 -> SMA Negeri 16 Palembang1900 | BG3: =S3&AU3&AD3 -> SMA Negeri 16 Palembang1900 | BH3: =S3&AV3&AD3 -> SMA Negeri 16 Palembang1900 | BI3: =S3&AW3&AD3 -> SMA Negeri 16 Palembang1900 | BJ3: =S3&AX3&AD3 -> SMA Negeri 16 Palembang1900 | BK3: =S3&AY3&AD3 -> SMA Negeri 16 Palembang1900 | BL3: =S3&AZ3&AD3 -> SMA Negeri 16 Palembang1900 | BM3: =S3&BA3&AD3 -> SMA Negeri 16 Palembang1900 | BN3: =S3&BB3&AD3 -> SMA Negeri 16 Palembang1900 | BO3: =S3&BC3&AD3 -> SMA Negeri 16 Palembang1900
B4: 5430 | D4: 5431 | E4: 6 | F4: Maret | G4: 2026 | H4: =VLOOKUP(F4,MASTER!$B$2:$C$13,2,FALSE) -> III | I4: Pemberian Izin Melakukan Field Project | J4: 0359/UN9.FK/SB2.AF.AF1/2026 | K4: 23 Februari 2026 | L4: Dekan Fakultas Kedokteran Universitas Sriwijaya | M4: Izin Melakukan Field Project | O4: Naira Siti Nuriah | P4: 04041282328027 | Q4: NIM | R4: Program Studi Psikologi Fakultas Kedokteran Universitas Sriwijaya | S4: SMA Negeri 16 Palembang | T4: =IF(Q4="NIM","Mahasiswa","Peserta Didik") -> Mahasiswa | U4: Universitas Sriwijaya | Z4: SELESAI | AA4: =IF(ISNA(MATCH(O4,SERTIFIKAT!$G$2:$G$237,0)),"","SERTIFIKAT SELESAI") | AB4: =MONTH(V4) -> 1 | AC4: =MONTH(W4) -> 1 | AD4: =YEAR(V4) -> 1900 | AE4: =YEAR(W4) -> 1900 | AF4: =AB4 -> 1 | AG4: =AF4+1 -> 2 | AH4: =AG4+1 -> 3 | AI4: =AH4+1 -> 4 | AJ4: =AI4+1 -> 5 | AK4: =AJ4+1 -> 6 | AL4: =AK4+1 -> 7 | AM4: =AL4+1 -> 8 | AN4: =AM4+1 -> 9 | ... AQ4: =AP4+1 -> 12 | AR4: =IF(AF4<AC4+1,AF4,"") -> 1 | AS4: =IF(AG4<AC4+1,AG4,"") | AT4: =IF(AH4<AC4+1,AH4,"") | AU4: =IF(AI4<AC4+1,AI4,"") | AV4: =IF(AJ4<AC4+1,AJ4,"") | AW4: =IF(AK4<AC4+1,AK4,"") | AX4: =IF(AL4<AC4+1,AL4,"") | AY4: =IF(AM4<AC4+1,AM4,"") | AZ4: =IF(AN4<AC4+1,AN4,"") | BA4: =IF(AO4<AC4+1,AO4,"") | BB4: =IF(AP4<AC4+1,AP4,"") | BC4: =IF(AQ4<AC4+1,AQ4,"") | BD4: =S4&AR4&AD4 -> SMA Negeri 16 Palembang11900 | BE4: =S4&AS4&AD4 -> SMA Negeri 16 Palembang1900 | BF4: =S4&AT4&AD4 -> SMA Negeri 16 Palembang1900 | BG4: =S4&AU4&AD4 -> SMA Negeri 16 Palembang1900 | BH4: =S4&AV4&AD4 -> SMA Negeri 16 Palembang1900 | BI4: =S4&AW4&AD4 -> SMA Negeri 16 Palembang1900 | BJ4: =S4&AX4&AD4 -> SMA Negeri 16 Palembang1900 | BK4: =S4&AY4&AD4 -> SMA Negeri 16 Palembang1900 | BL4: =S4&AZ4&AD4 -> SMA Negeri 16 Palembang1900 | BM4: =S4&BA4&AD4 -> SMA Negeri 16 Palembang1900 | BN4: =S4&BB4&AD4 -> SMA Negeri 16 Palembang1900 | BO4: =S4&BC4&AD4 -> SMA Negeri 16 Palembang1900
B5: 5430 | D5: 5431 | E5: 6 | F5: Maret | G5: 2026 | H5: =VLOOKUP(F5,MASTER!$B$2:$C$13,2,FALSE) -> III | I5: Pemberian Izin Melakukan Field Project | J5: 0359/UN9.FK/SB2.AF.AF1/2026 | K5: 23 Februari 2026 | L5: Dekan Fakultas Kedokteran Universitas Sriwijaya | M5: Izin Melakukan Field Project | O5: Angelica Winda Aliza | P5: 04041282328050 | Q5: NIM | R5: Program Studi Psikologi Fakultas Kedokteran Universitas Sriwijaya | S5: SMA Negeri 16 Palembang | T5: =IF(Q5="NIM","Mahasiswa","Peserta Didik") -> Mahasiswa | U5: Universitas Sriwijaya | Z5: SELESAI | AA5: =IF(ISNA(MATCH(O5,SERTIFIKAT!$G$2:$G$237,0)),"","SERTIFIKAT SELESAI") | AB5: =MONTH(V5) -> 1 | AC5: =MONTH(W5) -> 1 | AD5: =YEAR(V5) -> 1900 | AE5: =YEAR(W5) -> 1900 | AF5: =AB5 -> 1 | AG5: =AF5+1 -> 2 | AH5: =AG5+1 -> 3 | AI5: =AH5+1 -> 4 | AJ5: =AI5+1 -> 5 | AK5: =AJ5+1 -> 6 | AL5: =AK5+1 -> 7 | AM5: =AL5+1 -> 8 | AN5: =AM5+1 -> 9 | ... AQ5: =AP5+1 -> 12 | AR5: =IF(AF5<AC5+1,AF5,"") -> 1 | AS5: =IF(AG5<AC5+1,AG5,"") | AT5: =IF(AH5<AC5+1,AH5,"") | AU5: =IF(AI5<AC5+1,AI5,"") | AV5: =IF(AJ5<AC5+1,AJ5,"") | AW5: =IF(AK5<AC5+1,AK5,"") | AX5: =IF(AL5<AC5+1,AL5,"") | AY5: =IF(AM5<AC5+1,AM5,"") | AZ5: =IF(AN5<AC5+1,AN5,"") | BA5: =IF(AO5<AC5+1,AO5,"") | BB5: =IF(AP5<AC5+1,AP5,"") | BC5: =IF(AQ5<AC5+1,AQ5,"") | BD5: =S5&AR5&AD5 -> SMA Negeri 16 Palembang11900 | BE5: =S5&AS5&AD5 -> SMA Negeri 16 Palembang1900 | BF5: =S5&AT5&AD5 -> SMA Negeri 16 Palembang1900 | BG5: =S5&AU5&AD5 -> SMA Negeri 16 Palembang1900 | BH5: =S5&AV5&AD5 -> SMA Negeri 16 Palembang1900 | BI5: =S5&AW5&AD5 -> SMA Negeri 16 Palembang1900 | BJ5: =S5&AX5&AD5 -> SMA Negeri 16 Palembang1900 | BK5: =S5&AY5&AD5 -> SMA Negeri 16 Palembang1900 | BL5: =S5&AZ5&AD5 -> SMA Negeri 16 Palembang1900 | BM5: =S5&BA5&AD5 -> SMA Negeri 16 Palembang1900 | BN5: =S5&BB5&AD5 -> SMA Negeri 16 Palembang1900 | BO5: =S5&BC5&AD5 -> SMA Negeri 16 Palembang1900
B6: 5430 | D6: 5431 | E6: 6 | F6: Maret | G6: 2026 | H6: =VLOOKUP(F6,MASTER!$B$2:$C$13,2,FALSE) -> III | I6: Pemberian Izin Melakukan Field Project | J6: 0359/UN9.FK/SB2.AF.AF1/2026 | K6: 23 Februari 2026 | L6: Dekan Fakultas Kedokteran Universitas Sriwijaya | M6: Izin Melakukan Field Project | O6: Najma Adnine Shahab | P6: 04041282328057 | Q6: NIM | R6: Program Studi Psikologi Fakultas Kedokteran Universitas Sriwijaya | S6: SMA Negeri 16 Palembang | T6: =IF(Q6="NIM","Mahasiswa","Peserta Didik") -> Mahasiswa | U6: Universitas Sriwijaya | Z6: SELESAI | AA6: =IF(ISNA(MATCH(O6,SERTIFIKAT!$G$2:$G$237,0)),"","SERTIFIKAT SELESAI") | AB6: =MONTH(V6) -> 1 | AC6: =MONTH(W6) -> 1 | AD6: =YEAR(V6) -> 1900 | AE6: =YEAR(W6) -> 1900 | AF6: =AB6 -> 1 | AG6: =AF6+1 -> 2 | AH6: =AG6+1 -> 3 | AI6: =AH6+1 -> 4 | AJ6: =AI6+1 -> 5 | AK6: =AJ6+1 -> 6 | AL6: =AK6+1 -> 7 | AM6: =AL6+1 -> 8 | AN6: =AM6+1 -> 9 | ... AQ6: =AP6+1 -> 12 | AR6: =IF(AF6<AC6+1,AF6,"") -> 1 | AS6: =IF(AG6<AC6+1,AG6,"") | AT6: =IF(AH6<AC6+1,AH6,"") | AU6: =IF(AI6<AC6+1,AI6,"") | AV6: =IF(AJ6<AC6+1,AJ6,"") | AW6: =IF(AK6<AC6+1,AK6,"") | AX6: =IF(AL6<AC6+1,AL6,"") | AY6: =IF(AM6<AC6+1,AM6,"") | AZ6: =IF(AN6<AC6+1,AN6,"") | BA6: =IF(AO6<AC6+1,AO6,"") | BB6: =IF(AP6<AC6+1,AP6,"") | BC6: =IF(AQ6<AC6+1,AQ6,"") | BD6: =S6&AR6&AD6 -> SMA Negeri 16 Palembang11900 | BE6: =S6&AS6&AD6 -> SMA Negeri 16 Palembang1900 | BF6: =S6&AT6&AD6 -> SMA Negeri 16 Palembang1900 | BG6: =S6&AU6&AD6 -> SMA Negeri 16 Palembang1900 | BH6: =S6&AV6&AD6 -> SMA Negeri 16 Palembang1900 | BI6: =S6&AW6&AD6 -> SMA Negeri 16 Palembang1900 | BJ6: =S6&AX6&AD6 -> SMA Negeri 16 Palembang1900 | BK6: =S6&AY6&AD6 -> SMA Negeri 16 Palembang1900 | BL6: =S6&AZ6&AD6 -> SMA Negeri 16 Palembang1900 | BM6: =S6&BA6&AD6 -> SMA Negeri 16 Palembang1900 | BN6: =S6&BB6&AD6 -> SMA Negeri 16 Palembang1900 | BO6: =S6&BC6&AD6 -> SMA Negeri 16 Palembang1900
A7: 1 | O7: Yunita | Q7: NIM | S7: Subbagian Umum dan Kepegawaian | T7: =IF(Q7="NIM","Mahasiswa","Peserta Didik") -> Mahasiswa | U7: STIA Bala Putra Dewa | V7: 10 April 2026 | W7: 10 Mei 2026 | AB7: =MONTH(V7) -> 4 | AC7: =MONTH(W7) -> 5 | AD7: =YEAR(V7) -> 2026 | AE7: =YEAR(W7) -> 2026 | AF7: =AB7 -> 4 | AG7: =AF7+1 -> 5 | AH7: =AG7+1 -> 6 | AI7: =AH7+1 -> 7 | AJ7: =AI7+1 -> 8 | AK7: =AJ7+1 -> 9 | AL7: =AK7+1 -> 10 | AM7: =AL7+1 -> 11 | AN7: =AM7+1 -> 12 | ... AQ7: =AP7+1 -> 15 | AR7: =IF(AF7<AC7+1,AF7,"") -> 4 | AS7: =IF(AG7<AC7+1,AG7,"") -> 5 | AT7: =IF(AH7<AC7+1,AH7,"") | AU7: =IF(AI7<AC7+1,AI7,"") | AV7: =IF(AJ7<AC7+1,AJ7,"") | AW7: =IF(AK7<AC7+1,AK7,"") | AX7: =IF(AL7<AC7+1,AL7,"") | AY7: =IF(AM7<AC7+1,AM7,"") | AZ7: =IF(AN7<AC7+1,AN7,"") | BA7: =IF(AO7<AC7+1,AO7,"") | BB7: =IF(AP7<AC7+1,AP7,"") | BC7: =IF(AQ7<AC7+1,AQ7,"") | BD7: =S7&AR7&AD7 -> Subbagian Umum dan Kepegawaian42026 | BE7: =S7&AS7&AD7 -> Subbagian Umum dan Kepegawaian52026 | BF7: =S7&AT7&AD7 -> Subbagian Umum dan Kepegawaian2026 | BG7: =S7&AU7&AD7 -> Subbagian Umum dan Kepegawaian2026 | BH7: =S7&AV7&AD7 -> Subbagian Umum dan Kepegawaian2026 | BI7: =S7&AW7&AD7 -> Subbagian Umum dan Kepegawaian2026 | BJ7: =S7&AX7&AD7 -> Subbagian Umum dan Kepegawaian2026 | BK7: =S7&AY7&AD7 -> Subbagian Umum dan Kepegawaian2026 | BL7: =S7&AZ7&AD7 -> Subbagian Umum dan Kepegawaian2026 | BM7: =S7&BA7&AD7 -> Subbagian Umum dan Kepegawaian2026 | BN7: =S7&BB7&AD7 -> Subbagian Umum dan Kepegawaian2026 | BO7: =S7&BC7&AD7 -> Subbagian Umum dan Kepegawaian2026
A8: 2 | O8: Sri Wulandari | P8: 22320220 | Q8: NIM | R8: S1 Ilmu Administrasi Negara | S8: Subbagian Umum dan Kepegawaian | T8: =IF(Q8="NIM","Mahasiswa","Peserta Didik") -> Mahasiswa | U8: STIA Bala Putra Dewa | V8: 10 April 2026 | W8: 10 Mei 2026 | AA8: =IF(ISNA(MATCH(O8,SERTIFIKAT!$G$2:$G$237,0)),"","SERTIFIKAT SELESAI") | AB8: =MONTH(V8) -> 4 | AC8: =MONTH(W8) -> 5 | AD8: =YEAR(V8) -> 2026 | AE8: =YEAR(W8) -> 2026 | AF8: =AB8 -> 4 | AG8: =AF8+1 -> 5 | AH8: =AG8+1 -> 6 | AI8: =AH8+1 -> 7 | AJ8: =AI8+1 -> 8 | AK8: =AJ8+1 -> 9 | AL8: =AK8+1 -> 10 | AM8: =AL8+1 -> 11 | AN8: =AM8+1 -> 12 | ... AQ8: =AP8+1 -> 15 | AR8: =IF(AF8<AC8+1,AF8,"") -> 4 | AS8: =IF(AG8<AC8+1,AG8,"") -> 5 | AT8: =IF(AH8<AC8+1,AH8,"") | AU8: =IF(AI8<AC8+1,AI8,"") | AV8: =IF(AJ8<AC8+1,AJ8,"") | AW8: =IF(AK8<AC8+1,AK8,"") | AX8: =IF(AL8<AC8+1,AL8,"") | AY8: =IF(AM8<AC8+1,AM8,"") | AZ8: =IF(AN8<AC8+1,AN8,"") | BA8: =IF(AO8<AC8+1,AO8,"") | BB8: =IF(AP8<AC8+1,AP8,"") | BC8: =IF(AQ8<AC8+1,AQ8,"") | BD8: =S8&AR8&AD8 -> Subbagian Umum dan Kepegawaian42026 | BE8: =S8&AS8&AD8 -> Subbagian Umum dan Kepegawaian52026 | BF8: =S8&AT8&AD8 -> Subbagian Umum dan Kepegawaian2026 | BG8: =S8&AU8&AD8 -> Subbagian Umum dan Kepegawaian2026 | BH8: =S8&AV8&AD8 -> Subbagian Umum dan Kepegawaian2026 | BI8: =S8&AW8&AD8 -> Subbagian Umum dan Kepegawaian2026 | BJ8: =S8&AX8&AD8 -> Subbagian Umum dan Kepegawaian2026 | BK8: =S8&AY8&AD8 -> Subbagian Umum dan Kepegawaian2026 | BL8: =S8&AZ8&AD8 -> Subbagian Umum dan Kepegawaian2026 | BM8: =S8&BA8&AD8 -> Subbagian Umum dan Kepegawaian2026 | BN8: =S8&BB8&AD8 -> Subbagian Umum dan Kepegawaian2026 | BO8: =S8&BC8&AD8 -> Subbagian Umum dan Kepegawaian2026
A9: 3 | O9: M. Galang Ramadhan | Q9: NIS | S9: Subbagian Keuangan | T9: =IF(Q9="NIM","Mahasiswa","Peserta Didik") -> Peserta Didik | U9: SMKN BAKTI IBU 3 | V9: 02 Februari 2026 | W9: 04 Mei 2026 | AA9: =IF(ISNA(MATCH(O9,SERTIFIKAT!$G$2:$G$237,0)),"","SERTIFIKAT SELESAI") | AB9: =MONTH(V9) -> 2 | AC9: =MONTH(W9) -> 5 | AD9: =YEAR(V9) -> 2026 | AE9: =YEAR(W9) -> 2026 | AF9: =AB9 -> 2 | AG9: =AF9+1 -> 3 | AH9: =AG9+1 -> 4 | AI9: =AH9+1 -> 5 | AJ9: =AI9+1 -> 6 | AK9: =AJ9+1 -> 7 | AL9: =AK9+1 -> 8 | AM9: =AL9+1 -> 9 | AN9: =AM9+1 -> 10 | ... AQ9: =AP9+1 -> 13 | AR9: =IF(AF9<AC9+1,AF9,"") -> 2 | AS9: =IF(AG9<AC9+1,AG9,"") -> 3 | AT9: =IF(AH9<AC9+1,AH9,"") -> 4 | AU9: =IF(AI9<AC9+1,AI9,"") -> 5 | AV9: =IF(AJ9<AC9+1,AJ9,"") | AW9: =IF(AK9<AC9+1,AK9,"") | AX9: =IF(AL9<AC9+1,AL9,"") | AY9: =IF(AM9<AC9+1,AM9,"") | AZ9: =IF(AN9<AC9+1,AN9,"") | BA9: =IF(AO9<AC9+1,AO9,"") | BB9: =IF(AP9<AC9+1,AP9,"") | BC9: =IF(AQ9<AC9+1,AQ9,"") | BD9: =S9&AR9&AD9 -> Subbagian Keuangan22026 | BE9: =S9&AS9&AD9 -> Subbagian Keuangan32026 | BF9: =S9&AT9&AD9 -> Subbagian Keuangan42026 | BG9: =S9&AU9&AD9 -> Subbagian Keuangan52026 | BH9: =S9&AV9&AD9 -> Subbagian Keuangan2026 | BI9: =S9&AW9&AD9 -> Subbagian Keuangan2026 | BJ9: =S9&AX9&AD9 -> Subbagian Keuangan2026 | BK9: =S9&AY9&AD9 -> Subbagian Keuangan2026 | BL9: =S9&AZ9&AD9 -> Subbagian Keuangan2026 | BM9: =S9&BA9&AD9 -> Subbagian Keuangan2026 | BN9: =S9&BB9&AD9 -> Subbagian Keuangan2026 | BO9: =S9&BC9&AD9 -> Subbagian Keuangan2026
A10: 4 | O10: Nanda Dimas Firmansyah | Q10: NIS | S10: Seksi Peserta Didik SMK | T10: =IF(Q10="NIM","Mahasiswa","Peserta Didik") -> Peserta Didik | U10: SMKN BAKTI IBU 3 | V10: 02 Februari 2026 | W10: 04 Mei 2026 | AA10: =IF(ISNA(MATCH(O10,SERTIFIKAT!$G$2:$G$237,0)),"","SERTIFIKAT SELESAI") | AB10: =MONTH(V10) -> 2 | AC10: =MONTH(W10) -> 5 | AD10: =YEAR(V10) -> 2026 | AE10: =YEAR(W10) -> 2026 | AF10: =AB10 -> 2 | AG10: =AF10+1 -> 3 | AH10: =AG10+1 -> 4 | AI10: =AH10+1 -> 5 | AJ10: =AI10+1 -> 6 | AK10: =AJ10+1 -> 7 | AL10: =AK10+1 -> 8 | AM10: =AL10+1 -> 9 | AN10: =AM10+1 -> 10 | ... AQ10: =AP10+1 -> 13 | AR10: =IF(AF10<AC10+1,AF10,"") -> 2 | AS10: =IF(AG10<AC10+1,AG10,"") -> 3 | AT10: =IF(AH10<AC10+1,AH10,"") -> 4 | AU10: =IF(AI10<AC10+1,AI10,"") -> 5 | AV10: =IF(AJ10<AC10+1,AJ10,"") | AW10: =IF(AK10<AC10+1,AK10,"") | AX10: =IF(AL10<AC10+1,AL10,"") | AY10: =IF(AM10<AC10+1,AM10,"") | AZ10: =IF(AN10<AC10+1,AN10,"") | BA10: =IF(AO10<AC10+1,AO10,"") | BB10: =IF(AP10<AC10+1,AP10,"") | BC10: =IF(AQ10<AC10+1,AQ10,"") | BD10: =S10&AR10&AD10 -> Seksi Peserta Didik SMK22026 | BE10: =S10&AS10&AD10 -> Seksi Peserta Didik SMK32026 | BF10: =S10&AT10&AD10 -> Seksi Peserta Didik SMK42026 | BG10: =S10&AU10&AD10 -> Seksi Peserta Didik SMK52026 | BH10: =S10&AV10&AD10 -> Seksi Peserta Didik SMK2026 | BI10: =S10&AW10&AD10 -> Seksi Peserta Didik SMK2026 | BJ10: =S10&AX10&AD10 -> Seksi Peserta Didik SMK2026 | BK10: =S10&AY10&AD10 -> Seksi Peserta Didik SMK2026 | BL10: =S10&AZ10&AD10 -> Seksi Peserta Didik SMK2026 | BM10: =S10&BA10&AD10 -> Seksi Peserta Didik SMK2026 | BN10: =S10&BB10&AD10 -> Seksi Peserta Didik SMK2026 | BO10: =S10&BC10&AD10 -> Seksi Peserta Didik SMK2026
A11: 5 | O11: Rapit Angga Saputra | Q11: NIS | S11: Seksi Peserta Didik SMK | T11: =IF(Q11="NIM","Mahasiswa","Peserta Didik") -> Peserta Didik | U11: SMKN BAKTI IBU 3 | V11: 02 Februari 2026 | W11: 04 Mei 2026 | AA11: =IF(ISNA(MATCH(O11,SERTIFIKAT!$G$2:$G$237,0)),"","SERTIFIKAT SELESAI") | AB11: =MONTH(V11) -> 2 | AC11: =MONTH(W11) -> 5 | AD11: =YEAR(V11) -> 2026 | AE11: =YEAR(W11) -> 2026 | AF11: =AB11 -> 2 | AG11: =AF11+1 -> 3 | AH11: =AG11+1 -> 4 | AI11: =AH11+1 -> 5 | AJ11: =AI11+1 -> 6 | AK11: =AJ11+1 -> 7 | AL11: =AK11+1 -> 8 | AM11: =AL11+1 -> 9 | AN11: =AM11+1 -> 10 | ... AQ11: =AP11+1 -> 13 | AR11: =IF(AF11<AC11+1,AF11,"") -> 2 | AS11: =IF(AG11<AC11+1,AG11,"") -> 3 | AT11: =IF(AH11<AC11+1,AH11,"") -> 4 | AU11: =IF(AI11<AC11+1,AI11,"") -> 5 | AV11: =IF(AJ11<AC11+1,AJ11,"") | AW11: =IF(AK11<AC11+1,AK11,"") | AX11: =IF(AL11<AC11+1,AL11,"") | AY11: =IF(AM11<AC11+1,AM11,"") | AZ11: =IF(AN11<AC11+1,AN11,"") | BA11: =IF(AO11<AC11+1,AO11,"") | BB11: =IF(AP11<AC11+1,AP11,"") | BC11: =IF(AQ11<AC11+1,AQ11,"") | BD11: =S11&AR11&AD11 -> Seksi Peserta Didik SMK22026 | BE11: =S11&AS11&AD11 -> Seksi Peserta Didik SMK32026 | BF11: =S11&AT11&AD11 -> Seksi Peserta Didik SMK42026 | BG11: =S11&AU11&AD11 -> Seksi Peserta Didik SMK52026 | BH11: =S11&AV11&AD11 -> Seksi Peserta Didik SMK2026 | BI11: =S11&AW11&AD11 -> Seksi Peserta Didik SMK2026 | BJ11: =S11&AX11&AD11 -> Seksi Peserta Didik SMK2026 | BK11: =S11&AY11&AD11 -> Seksi Peserta Didik SMK2026 | BL11: =S11&AZ11&AD11 -> Seksi Peserta Didik SMK2026 | BM11: =S11&BA11&AD11 -> Seksi Peserta Didik SMK2026 | BN11: =S11&BB11&AD11 -> Seksi Peserta Didik SMK2026 | BO11: =S11&BC11&AD11 -> Seksi Peserta Didik SMK2026
A12: 6 | O12: Satria Fahri Kencana | Q12: NIS | S12: Subbagian Keuangan | T12: =IF(Q12="NIM","Mahasiswa","Peserta Didik") -> Peserta Didik | U12: SMKN BAKTI IBU 3 | V12: 02 Februari 2026 | W12: 04 Mei 2026 | AA12: =IF(ISNA(MATCH(O12,SERTIFIKAT!$G$2:$G$237,0)),"","SERTIFIKAT SELESAI") | AB12: =MONTH(V12) -> 2 | AC12: =MONTH(W12) -> 5 | AD12: =YEAR(V12) -> 2026 | AE12: =YEAR(W12) -> 2026 | AF12: =AB12 -> 2 | AG12: =AF12+1 -> 3 | AH12: =AG12+1 -> 4 | AI12: =AH12+1 -> 5 | AJ12: =AI12+1 -> 6 | AK12: =AJ12+1 -> 7 | AL12: =AK12+1 -> 8 | AM12: =AL12+1 -> 9 | AN12: =AM12+1 -> 10 | ... AQ12: =AP12+1 -> 13 | AR12: =IF(AF12<AC12+1,AF12,"") -> 2 | AS12: =IF(AG12<AC12+1,AG12,"") -> 3 | AT12: =IF(AH12<AC12+1,AH12,"") -> 4 | AU12: =IF(AI12<AC12+1,AI12,"") -> 5 | AV12: =IF(AJ12<AC12+1,AJ12,"") | AW12: =IF(AK12<AC12+1,AK12,"") | AX12: =IF(AL12<AC12+1,AL12,"") | AY12: =IF(AM12<AC12+1,AM12,"") | AZ12: =IF(AN12<AC12+1,AN12,"") | BA12: =IF(AO12<AC12+1,AO12,"") | BB12: =IF(AP12<AC12+1,AP12,"") | BC12: =IF(AQ12<AC12+1,AQ12,"") | BD12: =S12&AR12&AD12 -> Subbagian Keuangan22026 | BE12: =S12&AS12&AD12 -> Subbagian Keuangan32026 | BF12: =S12&AT12&AD12 -> Subbagian Keuangan42026 | BG12: =S12&AU12&AD12 -> Subbagian Keuangan52026 | BH12: =S12&AV12&AD12 -> Subbagian Keuangan2026 | BI12: =S12&AW12&AD12 -> Subbagian Keuangan2026 | BJ12: =S12&AX12&AD12 -> Subbagian Keuangan2026 | BK12: =S12&AY12&AD12 -> Subbagian Keuangan2026 | BL12: =S12&AZ12&AD12 -> Subbagian Keuangan2026 | BM12: =S12&BA12&AD12 -> Subbagian Keuangan2026 | BN12: =S12&BB12&AD12 -> Subbagian Keuangan2026 | BO12: =S12&BC12&AD12 -> Subbagian Keuangan2026
A13: 7 | O13: Keysha Amanda Dinanti | Q13: NIS | S13: Seksi Tugas Pembantuan | T13: =IF(Q13="NIM","Mahasiswa","Peserta Didik") -> Peserta Didik | U13: SMKN BAKTI IBU 3 | V13: 02 Februari 2026 | W13: 04 Mei 2026 | AA13: =IF(ISNA(MATCH(O13,SERTIFIKAT!$G$2:$G$237,0)),"","SERTIFIKAT SELESAI") | AB13: =MONTH(V13) -> 2 | AC13: =MONTH(W13) -> 5 | AD13: =YEAR(V13) -> 2026 | AE13: =YEAR(W13) -> 2026 | AF13: =AB13 -> 2 | AG13: =AF13+1 -> 3 | AH13: =AG13+1 -> 4 | AI13: =AH13+1 -> 5 | AJ13: =AI13+1 -> 6 | AK13: =AJ13+1 -> 7 | AL13: =AK13+1 -> 8 | AM13: =AL13+1 -> 9 | AN13: =AM13+1 -> 10 | ... AQ13: =AP13+1 -> 13 | AR13: =IF(AF13<AC13+1,AF13,"") -> 2 | AS13: =IF(AG13<AC13+1,AG13,"") -> 3 | AT13: =IF(AH13<AC13+1,AH13,"") -> 4 | AU13: =IF(AI13<AC13+1,AI13,"") -> 5 | AV13: =IF(AJ13<AC13+1,AJ13,"") | AW13: =IF(AK13<AC13+1,AK13,"") | AX13: =IF(AL13<AC13+1,AL13,"") | AY13: =IF(AM13<AC13+1,AM13,"") | AZ13: =IF(AN13<AC13+1,AN13,"") | BA13: =IF(AO13<AC13+1,AO13,"") | BB13: =IF(AP13<AC13+1,AP13,"") | BC13: =IF(AQ13<AC13+1,AQ13,"") | BD13: =S13&AR13&AD13 -> Seksi Tugas Pembantuan22026 | BE13: =S13&AS13&AD13 -> Seksi Tugas Pembantuan32026 | BF13: =S13&AT13&AD13 -> Seksi Tugas Pembantuan42026 | BG13: =S13&AU13&AD13 -> Seksi Tugas Pembantuan52026 | BH13: =S13&AV13&AD13 -> Seksi Tugas Pembantuan2026 | BI13: =S13&AW13&AD13 -> Seksi Tugas Pembantuan2026 | BJ13: =S13&AX13&AD13 -> Seksi Tugas Pembantuan2026 | BK13: =S13&AY13&AD13 -> Seksi Tugas Pembantuan2026 | BL13: =S13&AZ13&AD13 -> Seksi Tugas Pembantuan2026 | BM13: =S13&BA13&AD13 -> Seksi Tugas Pembantuan2026 | BN13: =S13&BB13&AD13 -> Seksi Tugas Pembantuan2026 | BO13: =S13&BC13&AD13 -> Seksi Tugas Pembantuan2026
A14: 8 | O14: Meli Nabila Sasia | Q14: NIS | S14: SAPRAS | T14: =IF(Q14="NIM","Mahasiswa","Peserta Didik") -> Peserta Didik | U14: SMKN BAKTI IBU 3 | V14: 02 Februari 2026 | W14: 04 Mei 2026 | AA14: =IF(ISNA(MATCH(O14,SERTIFIKAT!$G$2:$G$237,0)),"","SERTIFIKAT SELESAI") | AB14: =MONTH(V14) -> 2 | AC14: =MONTH(W14) -> 5 | AD14: =YEAR(V14) -> 2026 | AE14: =YEAR(W14) -> 2026 | AF14: =AB14 -> 2 | AG14: =AF14+1 -> 3 | AH14: =AG14+1 -> 4 | AI14: =AH14+1 -> 5 | AJ14: =AI14+1 -> 6 | AK14: =AJ14+1 -> 7 | AL14: =AK14+1 -> 8 | AM14: =AL14+1 -> 9 | AN14: =AM14+1 -> 10 | ... AQ14: =AP14+1 -> 13 | AR14: =IF(AF14<AC14+1,AF14,"") -> 2 | AS14: =IF(AG14<AC14+1,AG14,"") -> 3 | AT14: =IF(AH14<AC14+1,AH14,"") -> 4 | AU14: =IF(AI14<AC14+1,AI14,"") -> 5 | AV14: =IF(AJ14<AC14+1,AJ14,"") | AW14: =IF(AK14<AC14+1,AK14,"") | AX14: =IF(AL14<AC14+1,AL14,"") | AY14: =IF(AM14<AC14+1,AM14,"") | AZ14: =IF(AN14<AC14+1,AN14,"") | BA14: =IF(AO14<AC14+1,AO14,"") | BB14: =IF(AP14<AC14+1,AP14,"") | BC14: =IF(AQ14<AC14+1,AQ14,"") | BD14: =S14&AR14&AD14 -> SAPRAS 22026 | BE14: =S14&AS14&AD14 -> SAPRAS 32026 | BF14: =S14&AT14&AD14 -> SAPRAS 42026 | BG14: =S14&AU14&AD14 -> SAPRAS 52026 | BH14: =S14&AV14&AD14 -> SAPRAS 2026 | BI14: =S14&AW14&AD14 -> SAPRAS 2026 | BJ14: =S14&AX14&AD14 -> SAPRAS 2026 | BK14: =S14&AY14&AD14 -> SAPRAS 2026 | BL14: =S14&AZ14&AD14 -> SAPRAS 2026 | BM14: =S14&BA14&AD14 -> SAPRAS 2026 | BN14: =S14&BB14&AD14 -> SAPRAS 2026 | BO14: =S14&BC14&AD14 -> SAPRAS 2026
A15: 9 | O15: Nadia Adinda Riyanti | Q15: NIS | S15: Seksi Kurikulum dan Peserta Didik | T15: =IF(Q15="NIM","Mahasiswa","Peserta Didik") -> Peserta Didik | U15: SMKN BAKTI IBU 3 | V15: 02 Februari 2026 | W15: 04 Mei 2026 | AA15: =IF(ISNA(MATCH(O15,SERTIFIKAT!$G$2:$G$237,0)),"","SERTIFIKAT SELESAI") | AB15: =MONTH(V15) -> 2 | AC15: =MONTH(W15) -> 5 | AD15: =YEAR(V15) -> 2026 | AE15: =YEAR(W15) -> 2026 | AF15: =AB15 -> 2 | AG15: =AF15+1 -> 3 | AH15: =AG15+1 -> 4 | AI15: =AH15+1 -> 5 | AJ15: =AI15+1 -> 6 | AK15: =AJ15+1 -> 7 | AL15: =AK15+1 -> 8 | AM15: =AL15+1 -> 9 | AN15: =AM15+1 -> 10 | ... AQ15: =AP15+1 -> 13 | AR15: =IF(AF15<AC15+1,AF15,"") -> 2 | AS15: =IF(AG15<AC15+1,AG15,"") -> 3 | AT15: =IF(AH15<AC15+1,AH15,"") -> 4 | AU15: =IF(AI15<AC15+1,AI15,"") -> 5 | AV15: =IF(AJ15<AC15+1,AJ15,"") | AW15: =IF(AK15<AC15+1,AK15,"") | AX15: =IF(AL15<AC15+1,AL15,"") | AY15: =IF(AM15<AC15+1,AM15,"") | AZ15: =IF(AN15<AC15+1,AN15,"") | BA15: =IF(AO15<AC15+1,AO15,"") | BB15: =IF(AP15<AC15+1,AP15,"") | BC15: =IF(AQ15<AC15+1,AQ15,"") | BD15: =S15&AR15&AD15 -> Seksi Kurikulum dan Peserta Didik22026 | BE15: =S15&AS15&AD15 -> Seksi Kurikulum dan Peserta Didik32026 | BF15: =S15&AT15&AD15 -> Seksi Kurikulum dan Peserta Didik42026 | BG15: =S15&AU15&AD15 -> Seksi Kurikulum dan Peserta Didik52026 | BH15: =S15&AV15&AD15 -> Seksi Kurikulum dan Peserta Didik2026 | BI15: =S15&AW15&AD15 -> Seksi Kurikulum dan Peserta Didik2026 | BJ15: =S15&AX15&AD15 -> Seksi Kurikulum dan Peserta Didik2026 | BK15: =S15&AY15&AD15 -> Seksi Kurikulum dan Peserta Didik2026 | BL15: =S15&AZ15&AD15 -> Seksi Kurikulum dan Peserta Didik2026 | BM15: =S15&BA15&AD15 -> Seksi Kurikulum dan Peserta Didik2026 | BN15: =S15&BB15&AD15 -> Seksi Kurikulum dan Peserta Didik2026 | BO15: =S15&BC15&AD15 -> Seksi Kurikulum dan Peserta Didik2026
A16: 10 | O16: Silvi Ramalia | Q16: NIS | S16: Seksi Kurikulum dan Peserta Didik | T16: =IF(Q16="NIM","Mahasiswa","Peserta Didik") -> Peserta Didik | U16: SMKN BAKTI IBU 3 | V16: 02 Februari 2026 | W16: 04 Mei 2026 | AA16: =IF(ISNA(MATCH(O16,SERTIFIKAT!$G$2:$G$237,0)),"","SERTIFIKAT SELESAI") | AB16: =MONTH(V16) -> 2 | AC16: =MONTH(W16) -> 5 | AD16: =YEAR(V16) -> 2026 | AE16: =YEAR(W16) -> 2026 | AF16: =AB16 -> 2 | AG16: =AF16+1 -> 3 | AH16: =AG16+1 -> 4 | AI16: =AH16+1 -> 5 | AJ16: =AI16+1 -> 6 | AK16: =AJ16+1 -> 7 | AL16: =AK16+1 -> 8 | AM16: =AL16+1 -> 9 | AN16: =AM16+1 -> 10 | ... AQ16: =AP16+1 -> 13 | AR16: =IF(AF16<AC16+1,AF16,"") -> 2 | AS16: =IF(AG16<AC16+1,AG16,"") -> 3 | AT16: =IF(AH16<AC16+1,AH16,"") -> 4 | AU16: =IF(AI16<AC16+1,AI16,"") -> 5 | AV16: =IF(AJ16<AC16+1,AJ16,"") | AW16: =IF(AK16<AC16+1,AK16,"") | AX16: =IF(AL16<AC16+1,AL16,"") | AY16: =IF(AM16<AC16+1,AM16,"") | AZ16: =IF(AN16<AC16+1,AN16,"") | BA16: =IF(AO16<AC16+1,AO16,"") | BB16: =IF(AP16<AC16+1,AP16,"") | BC16: =IF(AQ16<AC16+1,AQ16,"") | BD16: =S16&AR16&AD16 -> Seksi Kurikulum dan Peserta Didik22026 | BE16: =S16&AS16&AD16 -> Seksi Kurikulum dan Peserta Didik32026 | BF16: =S16&AT16&AD16 -> Seksi Kurikulum dan Peserta Didik42026 | BG16: =S16&AU16&AD16 -> Seksi Kurikulum dan Peserta Didik52026 | BH16: =S16&AV16&AD16 -> Seksi Kurikulum dan Peserta Didik2026 | BI16: =S16&AW16&AD16 -> Seksi Kurikulum dan Peserta Didik2026 | BJ16: =S16&AX16&AD16 -> Seksi Kurikulum dan Peserta Didik2026 | BK16: =S16&AY16&AD16 -> Seksi Kurikulum dan Peserta Didik2026 | BL16: =S16&AZ16&AD16 -> Seksi Kurikulum dan Peserta Didik2026 | BM16: =S16&BA16&AD16 -> Seksi Kurikulum dan Peserta Didik2026 | BN16: =S16&BB16&AD16 -> Seksi Kurikulum dan Peserta Didik2026 | BO16: =S16&BC16&AD16 -> Seksi Kurikulum dan Peserta Didik2026
A17: 11 | O17: Ahmad Nurdin | Q17: NIM | S17: Subbagian Perencanaan Evaluasi dan Pelaporan | T17: =IF(Q17="NIM","Mahasiswa","Peserta Didik") -> Mahasiswa | U17: POLSRI | V17: 09 Februari 2026 | W17: 12 Juni 2026 | AA17: =IF(ISNA(MATCH(O17,SERTIFIKAT!$G$2:$G$237,0)),"","SERTIFIKAT SELESAI") | AB17: =MONTH(V17) -> 2 | AC17: =MONTH(W17) -> 6 | AD17: =YEAR(V17) -> 2026 | AE17: =YEAR(W17) -> 2026 | AF17: =AB17 -> 2 | AG17: =AF17+1 -> 3 | AH17: =AG17+1 -> 4 | AI17: =AH17+1 -> 5 | AJ17: =AI17+1 -> 6 | AK17: =AJ17+1 -> 7 | AL17: =AK17+1 -> 8 | AM17: =AL17+1 -> 9 | AN17: =AM17+1 -> 10 | ... AQ17: =AP17+1 -> 13 | AR17: =IF(AF17<AC17+1,AF17,"") -> 2 | AS17: =IF(AG17<AC17+1,AG17,"") -> 3 | AT17: =IF(AH17<AC17+1,AH17,"") -> 4 | AU17: =IF(AI17<AC17+1,AI17,"") -> 5 | AV17: =IF(AJ17<AC17+1,AJ17,"") -> 6 | AW17: =IF(AK17<AC17+1,AK17,"") | AX17: =IF(AL17<AC17+1,AL17,"") | AY17: =IF(AM17<AC17+1,AM17,"") | AZ17: =IF(AN17<AC17+1,AN17,"") | BA17: =IF(AO17<AC17+1,AO17,"") | BB17: =IF(AP17<AC17+1,AP17,"") | BC17: =IF(AQ17<AC17+1,AQ17,"") | BD17: =S17&AR17&AD17 -> Subbagian Perencanaan Evaluasi dan Pelaporan22026 | BE17: =S17&AS17&AD17 -> Subbagian Perencanaan Evaluasi dan Pelaporan32026 | BF17: =S17&AT17&AD17 -> Subbagian Perencanaan Evaluasi dan Pelaporan42026 | BG17: =S17&AU17&AD17 -> Subbagian Perencanaan Evaluasi dan Pelaporan52026 | BH17: =S17&AV17&AD17 -> Subbagian Perencanaan Evaluasi dan Pelaporan62026 | BI17: =S17&AW17&AD17 -> Subbagian Perencanaan Evaluasi dan Pelaporan2026 | BJ17: =S17&AX17&AD17 -> Subbagian Perencanaan Evaluasi dan Pelaporan2026 | BK17: =S17&AY17&AD17 -> Subbagian Perencanaan Evaluasi dan Pelaporan2026 | BL17: =S17&AZ17&AD17 -> Subbagian Perencanaan Evaluasi dan Pelaporan2026 | BM17: =S17&BA17&AD17 -> Subbagian Perencanaan Evaluasi dan Pelaporan2026 | BN17: =S17&BB17&AD17 -> Subbagian Perencanaan Evaluasi dan Pelaporan2026 | BO17: =S17&BC17&AD17 -> Subbagian Perencanaan Evaluasi dan Pelaporan2026
A18: 12 | O18: M. Arif Kurniawan | Q18: NIM | S18: Subbagian Keuangan | T18: =IF(Q18="NIM","Mahasiswa","Peserta Didik") -> Mahasiswa | U18: POLSRI | V18: 09 Februari 2026 | W18: 12 Juni 2026 | AA18: =IF(ISNA(MATCH(O18,SERTIFIKAT!$G$2:$G$237,0)),"","SERTIFIKAT SELESAI") | AB18: =MONTH(V18) -> 2 | AC18: =MONTH(W18) -> 6 | AD18: =YEAR(V18) -> 2026 | AE18: =YEAR(W18) -> 2026 | AF18: =AB18 -> 2 | AG18: =AF18+1 -> 3 | AH18: =AG18+1 -> 4 | AI18: =AH18+1 -> 5 | AJ18: =AI18+1 -> 6 | AK18: =AJ18+1 -> 7 | AL18: =AK18+1 -> 8 | AM18: =AL18+1 -> 9 | AN18: =AM18+1 -> 10 | ... AQ18: =AP18+1 -> 13 | AR18: =IF(AF18<AC18+1,AF18,"") -> 2 | AS18: =IF(AG18<AC18+1,AG18,"") -> 3 | AT18: =IF(AH18<AC18+1,AH18,"") -> 4 | AU18: =IF(AI18<AC18+1,AI18,"") -> 5 | AV18: =IF(AJ18<AC18+1,AJ18,"") -> 6 | AW18: =IF(AK18<AC18+1,AK18,"") | AX18: =IF(AL18<AC18+1,AL18,"") | AY18: =IF(AM18<AC18+1,AM18,"") | AZ18: =IF(AN18<AC18+1,AN18,"") | BA18: =IF(AO18<AC18+1,AO18,"") | BB18: =IF(AP18<AC18+1,AP18,"") | BC18: =IF(AQ18<AC18+1,AQ18,"") | BD18: =S18&AR18&AD18 -> Subbagian Keuangan22026 | BE18: =S18&AS18&AD18 -> Subbagian Keuangan32026 | BF18: =S18&AT18&AD18 -> Subbagian Keuangan42026 | BG18: =S18&AU18&AD18 -> Subbagian Keuangan52026 | BH18: =S18&AV18&AD18 -> Subbagian Keuangan62026 | BI18: =S18&AW18&AD18 -> Subbagian Keuangan2026 | BJ18: =S18&AX18&AD18 -> Subbagian Keuangan2026 | BK18: =S18&AY18&AD18 -> Subbagian Keuangan2026 | BL18: =S18&AZ18&AD18 -> Subbagian Keuangan2026 | BM18: =S18&BA18&AD18 -> Subbagian Keuangan2026 | BN18: =S18&BB18&AD18 -> Subbagian Keuangan2026 | BO18: =S18&BC18&AD18 -> Subbagian Keuangan2026
A19: 13 | O19: Muhammad Hazel S. | Q19: NIM | S19: Seksi PTK SMA | T19: =IF(Q19="NIM","Mahasiswa","Peserta Didik") -> Mahasiswa | U19: POLSRI | V19: 09 Februari 2026 | W19: 12 Juni 2026 | AA19: =IF(ISNA(MATCH(O19,SERTIFIKAT!$G$2:$G$237,0)),"","SERTIFIKAT SELESAI") | AB19: =MONTH(V19) -> 2 | AC19: =MONTH(W19) -> 6 | AD19: =YEAR(V19) -> 2026 | AE19: =YEAR(W19) -> 2026 | AF19: =AB19 -> 2 | AG19: =AF19+1 -> 3 | AH19: =AG19+1 -> 4 | AI19: =AH19+1 -> 5 | AJ19: =AI19+1 -> 6 | AK19: =AJ19+1 -> 7 | AL19: =AK19+1 -> 8 | AM19: =AL19+1 -> 9 | AN19: =AM19+1 -> 10 | ... AQ19: =AP19+1 -> 13 | AR19: =IF(AF19<AC19+1,AF19,"") -> 2 | AS19: =IF(AG19<AC19+1,AG19,"") -> 3 | AT19: =IF(AH19<AC19+1,AH19,"") -> 4 | AU19: =IF(AI19<AC19+1,AI19,"") -> 5 | AV19: =IF(AJ19<AC19+1,AJ19,"") -> 6 | AW19: =IF(AK19<AC19+1,AK19,"") | AX19: =IF(AL19<AC19+1,AL19,"") | AY19: =IF(AM19<AC19+1,AM19,"") | AZ19: =IF(AN19<AC19+1,AN19,"") | BA19: =IF(AO19<AC19+1,AO19,"") | BB19: =IF(AP19<AC19+1,AP19,"") | BC19: =IF(AQ19<AC19+1,AQ19,"") | BD19: =S19&AR19&AD19 -> Seksi PTK SMA22026 | BE19: =S19&AS19&AD19 -> Seksi PTK SMA32026 | BF19: =S19&AT19&AD19 -> Seksi PTK SMA42026 | BG19: =S19&AU19&AD19 -> Seksi PTK SMA52026 | BH19: =S19&AV19&AD19 -> Seksi PTK SMA62026 | BI19: =S19&AW19&AD19 -> Seksi PTK SMA2026 | BJ19: =S19&AX19&AD19 -> Seksi PTK SMA2026 | BK19: =S19&AY19&AD19 -> Seksi PTK SMA2026 | BL19: =S19&AZ19&AD19 -> Seksi PTK SMA2026 | BM19: =S19&BA19&AD19 -> Seksi PTK SMA2026 | BN19: =S19&BB19&AD19 -> Seksi PTK SMA2026 | BO19: =S19&BC19&AD19 -> Seksi PTK SMA2026
A20: 14 | O20: M. Ibnu Athailah F. | Q20: NIM | S20: Subbagian Perencanaan Evaluasi dan Pelaporan | T20: =IF(Q20="NIM","Mahasiswa","Peserta Didik") -> Mahasiswa | U20: POLSRI | V20: 09 Februari 2026 | W20: 12 Juni 2026 | AA20: =IF(ISNA(MATCH(O20,SERTIFIKAT!$G$2:$G$237,0)),"","SERTIFIKAT SELESAI") | AB20: =MONTH(V20) -> 2 | AC20: =MONTH(W20) -> 6 | AD20: =YEAR(V20) -> 2026 | AE20: =YEAR(W20) -> 2026 | AF20: =AB20 -> 2 | AG20: =AF20+1 -> 3 | AH20: =AG20+1 -> 4 | AI20: =AH20+1 -> 5 | AJ20: =AI20+1 -> 6 | AK20: =AJ20+1 -> 7 | AL20: =AK20+1 -> 8 | AM20: =AL20+1 -> 9 | AN20: =AM20+1 -> 10 | ... AQ20: =AP20+1 -> 13 | AR20: =IF(AF20<AC20+1,AF20,"") -> 2 | AS20: =IF(AG20<AC20+1,AG20,"") -> 3 | AT20: =IF(AH20<AC20+1,AH20,"") -> 4 | AU20: =IF(AI20<AC20+1,AI20,"") -> 5 | AV20: =IF(AJ20<AC20+1,AJ20,"") -> 6 | AW20: =IF(AK20<AC20+1,AK20,"") | AX20: =IF(AL20<AC20+1,AL20,"") | AY20: =IF(AM20<AC20+1,AM20,"") | AZ20: =IF(AN20<AC20+1,AN20,"") | BA20: =IF(AO20<AC20+1,AO20,"") | BB20: =IF(AP20<AC20+1,AP20,"") | BC20: =IF(AQ20<AC20+1,AQ20,"") | BD20: =S20&AR20&AD20 -> Subbagian Perencanaan Evaluasi dan Pelaporan22026 | BE20: =S20&AS20&AD20 -> Subbagian Perencanaan Evaluasi dan Pelaporan32026 | BF20: =S20&AT20&AD20 -> Subbagian Perencanaan Evaluasi dan Pelaporan42026 | BG20: =S20&AU20&AD20 -> Subbagian Perencanaan Evaluasi dan Pelaporan52026 | BH20: =S20&AV20&AD20 -> Subbagian Perencanaan Evaluasi dan Pelaporan62026 | BI20: =S20&AW20&AD20 -> Subbagian Perencanaan Evaluasi dan Pelaporan2026 | BJ20: =S20&AX20&AD20 -> Subbagian Perencanaan Evaluasi dan Pelaporan2026 | BK20: =S20&AY20&AD20 -> Subbagian Perencanaan Evaluasi dan Pelaporan2026 | BL20: =S20&AZ20&AD20 -> Subbagian Perencanaan Evaluasi dan Pelaporan2026 | BM20: =S20&BA20&AD20 -> Subbagian Perencanaan Evaluasi dan Pelaporan2026 | BN20: =S20&BB20&AD20 -> Subbagian Perencanaan Evaluasi dan Pelaporan2026 | BO20: =S20&BC20&AD20 -> Subbagian Perencanaan Evaluasi dan Pelaporan2026
... A24: 18 | O24: Restu Bernandy | Q24: NIM | S24: Subbagian Keuangan | T24: =IF(Q24="NIM","Mahasiswa","Peserta Didik") -> Mahasiswa | U24: POLSRI | V24: 09 Februari 2026 | W24: 12 Juni 2026 | AA24: =IF(ISNA(MATCH(O24,SERTIFIKAT!$G$2:$G$237,0)),"","SERTIFIKAT SELESAI") | AB24: =MONTH(V24) -> 2 | AC24: =MONTH(W24) -> 6 | AD24: =YEAR(V24) -> 2026 | AE24: =YEAR(W24) -> 2026 | AF24: =AB24 -> 2 | AG24: =AF24+1 -> 3 | AH24: =AG24+1 -> 4 | AI24: =AH24+1 -> 5 | AJ24: =AI24+1 -> 6 | AK24: =AJ24+1 -> 7 | AL24: =AK24+1 -> 8 | AM24: =AL24+1 -> 9 | AN24: =AM24+1 -> 10 | ... AQ24: =AP24+1 -> 13 | AR24: =IF(AF24<AC24+1,AF24,"") -> 2 | AS24: =IF(AG24<AC24+1,AG24,"") -> 3 | AT24: =IF(AH24<AC24+1,AH24,"") -> 4 | AU24: =IF(AI24<AC24+1,AI24,"") -> 5 | AV24: =IF(AJ24<AC24+1,AJ24,"") -> 6 | AW24: =IF(AK24<AC24+1,AK24,"") | AX24: =IF(AL24<AC24+1,AL24,"") | AY24: =IF(AM24<AC24+1,AM24,"") | AZ24: =IF(AN24<AC24+1,AN24,"") | BA24: =IF(AO24<AC24+1,AO24,"") | BB24: =IF(AP24<AC24+1,AP24,"") | BC24: =IF(AQ24<AC24+1,AQ24,"") | BD24: =S24&AR24&AD24 -> Subbagian Keuangan22026 | BE24: =S24&AS24&AD24 -> Subbagian Keuangan32026 | BF24: =S24&AT24&AD24 -> Subbagian Keuangan42026 | BG24: =S24&AU24&AD24 -> Subbagian Keuangan52026 | BH24: =S24&AV24&AD24 -> Subbagian Keuangan62026 | BI24: =S24&AW24&AD24 -> Subbagian Keuangan2026 | BJ24: =S24&AX24&AD24 -> Subbagian Keuangan2026 | BK24: =S24&AY24&AD24 -> Subbagian Keuangan2026 | BL24: =S24&AZ24&AD24 -> Subbagian Keuangan2026 | BM24: =S24&BA24&AD24 -> Subbagian Keuangan2026 | BN24: =S24&BB24&AD24 -> Subbagian Keuangan2026 | BO24: =S24&BC24&AD24 -> Subbagian Keuangan2026
O25: Wulan Priyatma Putri | P25: 42742 | Q25: NIS | R25: TKJ | S25: Seksi Kurikulum SMA | T25: =IF(Q25="NIM","Mahasiswa","Peserta Didik") -> Peserta Didik | U25: SMK Negeri 2 Palembang | V25: 20 Juli 2026 | W25: 06 Desember 2026 | AA25: =IF(ISNA(MATCH(O25,SERTIFIKAT!$G$2:$G$237,0)),"","SERTIFIKAT SELESAI") | AB25: =MONTH(V25) -> 7 | AC25: =MONTH(W25) -> 12 | AD25: =YEAR(V25) -> 2026 | AE25: =YEAR(W25) -> 2026 | AF25: =AB25 -> 7 | AG25: =AF25+1 -> 8 | AH25: =AG25+1 -> 9 | AI25: =AH25+1 -> 10 | AJ25: =AI25+1 -> 11 | AK25: =AJ25+1 -> 12 | AL25: =AK25+1 -> 13 | AM25: =AL25+1 -> 14 | AN25: =AM25+1 -> 15 | ... AQ25: =AP25+1 -> 18 | AR25: =IF(AF25<AC25+1,AF25,"") -> 7 | AS25: =IF(AG25<AC25+1,AG25,"") -> 8 | AT25: =IF(AH25<AC25+1,AH25,"") -> 9 | AU25: =IF(AI25<AC25+1,AI25,"") -> 10 | AV25: =IF(AJ25<AC25+1,AJ25,"") -> 11 | AW25: =IF(AK25<AC25+1,AK25,"") -> 12 | AX25: =IF(AL25<AC25+1,AL25,"") | AY25: =IF(AM25<AC25+1,AM25,"") | AZ25: =IF(AN25<AC25+1,AN25,"") | BA25: =IF(AO25<AC25+1,AO25,"") | BB25: =IF(AP25<AC25+1,AP25,"") | BC25: =IF(AQ25<AC25+1,AQ25,"") | BD25: =S25&AR25&AD25 -> Seksi Kurikulum SMA72026 | BE25: =S25&AS25&AD25 -> Seksi Kurikulum SMA82026 | BF25: =S25&AT25&AD25 -> Seksi Kurikulum SMA92026 | BG25: =S25&AU25&AD25 -> Seksi Kurikulum SMA102026 | BH25: =S25&AV25&AD25 -> Seksi Kurikulum SMA112026 | BI25: =S25&AW25&AD25 -> Seksi Kurikulum SMA122026 | BJ25: =S25&AX25&AD25 -> Seksi Kurikulum SMA2026 | BK25: =S25&AY25&AD25 -> Seksi Kurikulum SMA2026 | BL25: =S25&AZ25&AD25 -> Seksi Kurikulum SMA2026 | BM25: =S25&BA25&AD25 -> Seksi Kurikulum SMA2026 | BN25: =S25&BB25&AD25 -> Seksi Kurikulum SMA2026 | BO25: =S25&BC25&AD25 -> Seksi Kurikulum SMA2026
O26: Tiara Merva Mafira | P26: 42738 | Q26: NIS | R26: TKJ | S26: Seksi Peserta Didik SMA | T26: =IF(Q26="NIM","Mahasiswa","Peserta Didik") -> Peserta Didik | U26: SMK Negeri 2 Palembang | V26: 20 Juli 2026 | W26: 06 Desember 2026 | AA26: =IF(ISNA(MATCH(O26,SERTIFIKAT!$G$2:$G$237,0)),"","SERTIFIKAT SELESAI") | AB26: =MONTH(V26) -> 7 | AC26: =MONTH(W26) -> 12 | AD26: =YEAR(V26) -> 2026 | AE26: =YEAR(W26) -> 2026 | AF26: =AB26 -> 7 | AG26: =AF26+1 -> 8 | AH26: =AG26+1 -> 9 | AI26: =AH26+1 -> 10 | AJ26: =AI26+1 -> 11 | AK26: =AJ26+1 -> 12 | AL26: =AK26+1 -> 13 | AM26: =AL26+1 -> 14 | AN26: =AM26+1 -> 15 | ... AQ26: =AP26+1 -> 18 | AR26: =IF(AF26<AC26+1,AF26,"") -> 7 | AS26: =IF(AG26<AC26+1,AG26,"") -> 8 | AT26: =IF(AH26<AC26+1,AH26,"") -> 9 | AU26: =IF(AI26<AC26+1,AI26,"") -> 10 | AV26: =IF(AJ26<AC26+1,AJ26,"") -> 11 | AW26: =IF(AK26<AC26+1,AK26,"") -> 12 | AX26: =IF(AL26<AC26+1,AL26,"") | AY26: =IF(AM26<AC26+1,AM26,"") | AZ26: =IF(AN26<AC26+1,AN26,"") | BA26: =IF(AO26<AC26+1,AO26,"") | BB26: =IF(AP26<AC26+1,AP26,"") | BC26: =IF(AQ26<AC26+1,AQ26,"") | BD26: =S26&AR26&AD26 -> Seksi Peserta Didik SMA72026 | BE26: =S26&AS26&AD26 -> Seksi Peserta Didik SMA82026 | BF26: =S26&AT26&AD26 -> Seksi Peserta Didik SMA92026 | BG26: =S26&AU26&AD26 -> Seksi Peserta Didik SMA102026 | BH26: =S26&AV26&AD26 -> Seksi Peserta Didik SMA112026 | BI26: =S26&AW26&AD26 -> Seksi Peserta Didik SMA122026 | BJ26: =S26&AX26&AD26 -> Seksi Peserta Didik SMA2026 | BK26: =S26&AY26&AD26 -> Seksi Peserta Didik SMA2026 | BL26: =S26&AZ26&AD26 -> Seksi Peserta Didik SMA2026 | BM26: =S26&BA26&AD26 -> Seksi Peserta Didik SMA2026 | BN26: =S26&BB26&AD26 -> Seksi Peserta Didik SMA2026 | BO26: =S26&BC26&AD26 -> Seksi Peserta Didik SMA2026
B27: 6692 | C27: 6693 | E27: 14 | F27: April | G27: 2026 | H27: =VLOOKUP(F27,MASTER!$B$2:$C$13,2,FALSE) -> IV | I27: Praktek Kerja Lapangan | J27: 400.145.4/0738/Diskominfo/2026 | K27: 27 Maret 2026 | L27: Sekretaris Daerah | M27: Praktek Kerja Lapangan | N27: Kepala Program Studi Sistem Informasi UIN Raden Fatah Palembang | O27: M. Ezra Hilmidin Kafa | P27: 23051450187 | Q27: NIM | R27: Program Studi Sistem Informasi | S27: Subbagian Umum dan Kepegawaian | T27: =IF(Q27="NIM","Mahasiswa","Peserta Didik") -> Mahasiswa | U27: UIN Raden Fatah Palembang | V27: 14 April 2026 | W27: 14 Juli 2026 | X27: Kepala Dinas Kominfo Provinsi Sumatera Selatan | Y27: Kepala Program Studi Sistem Informasi UIN Raden Fatah Palembang | AA27: =IF(ISNA(MATCH(O27,SERTIFIKAT!$G$2:$G$237,0)),"","SERTIFIKAT SELESAI") | AB27: =MONTH(V27) -> 4 | AC27: =MONTH(W27) -> 7 | AD27: =YEAR(V27) -> 2026 | AE27: =YEAR(W27) -> 2026 | AF27: =AB27 -> 4 | AG27: =AF27+1 -> 5 | AH27: =AG27+1 -> 6 | AI27: =AH27+1 -> 7 | AJ27: =AI27+1 -> 8 | AK27: =AJ27+1 -> 9 | AL27: =AK27+1 -> 10 | AM27: =AL27+1 -> 11 | AN27: =AM27+1 -> 12 | ... AQ27: =AP27+1 -> 15 | AR27: =IF(AF27<AC27+1,AF27,"") -> 4 | AS27: =IF(AG27<AC27+1,AG27,"") -> 5 | AT27: =IF(AH27<AC27+1,AH27,"") -> 6 | AU27: =IF(AI27<AC27+1,AI27,"") -> 7 | AV27: =IF(AJ27<AC27+1,AJ27,"") | AW27: =IF(AK27<AC27+1,AK27,"") | AX27: =IF(AL27<AC27+1,AL27,"") | AY27: =IF(AM27<AC27+1,AM27,"") | AZ27: =IF(AN27<AC27+1,AN27,"") | BA27: =IF(AO27<AC27+1,AO27,"") | BB27: =IF(AP27<AC27+1,AP27,"") | BC27: =IF(AQ27<AC27+1,AQ27,"") | BD27: =S27&AR27&AD27 -> Subbagian Umum dan Kepegawaian42026 | BE27: =S27&AS27&AD27 -> Subbagian Umum dan Kepegawaian52026 | BF27: =S27&AT27&AD27 -> Subbagian Umum dan Kepegawaian62026 | BG27: =S27&AU27&AD27 -> Subbagian Umum dan Kepegawaian72026 | BH27: =S27&AV27&AD27 -> Subbagian Umum dan Kepegawaian2026 | BI27: =S27&AW27&AD27 -> Subbagian Umum dan Kepegawaian2026 | BJ27: =S27&AX27&AD27 -> Subbagian Umum dan Kepegawaian2026 | BK27: =S27&AY27&AD27 -> Subbagian Umum dan Kepegawaian2026 | BL27: =S27&AZ27&AD27 -> Subbagian Umum dan Kepegawaian2026 | BM27: =S27&BA27&AD27 -> Subbagian Umum dan Kepegawaian2026 | BN27: =S27&BB27&AD27 -> Subbagian Umum dan Kepegawaian2026 | BO27: =S27&BC27&AD27 -> Subbagian Umum dan Kepegawaian2026
B28: 6694 | C28: 6695 | E28: 14 | F28: April | G28: 2026 | H28: =VLOOKUP(F28,MASTER!$B$2:$C$13,2,FALSE) -> IV | I28: Praktek Kerja Lapangan | J28: 400.145.4/0738/Diskominfo/2026 | K28: 27 Maret 2026 | L28: Sekretaris Daerah | M28: Praktek Kerja Lapangan | N28: Kepala Program Studi Teknik Informatika Universitas Bina Darma Palembang | O28: Rahmat Yusuf | P28: 231420109 | Q28: NIM | R28: Program Studi Teknik Informatika | S28: Subbagian Perencanaan Evaluasi dan Pelaporan | T28: =IF(Q28="NIM","Mahasiswa","Peserta Didik") -> Mahasiswa | U28: Universitas Bina Darma Palembang | V28: 14 April 2026 | W28: 14 Juli 2026 | X28: Kepala Dinas Kominfo Provinsi Sumatera Selatan | Y28: Kepala Program Studi Teknik Informatika Universitas Bina Darma Palembang | AA28: =IF(ISNA(MATCH(O28,SERTIFIKAT!$G$2:$G$237,0)),"","SERTIFIKAT SELESAI") | AB28: =MONTH(V28) -> 4 | AC28: =MONTH(W28) -> 7 | AD28: =YEAR(V28) -> 2026 | AE28: =YEAR(W28) -> 2026 | AF28: =AB28 -> 4 | AG28: =AF28+1 -> 5 | AH28: =AG28+1 -> 6 | AI28: =AH28+1 -> 7 | AJ28: =AI28+1 -> 8 | AK28: =AJ28+1 -> 9 | AL28: =AK28+1 -> 10 | AM28: =AL28+1 -> 11 | AN28: =AM28+1 -> 12 | ... AQ28: =AP28+1 -> 15 | AR28: =IF(AF28<AC28+1,AF28,"") -> 4 | AS28: =IF(AG28<AC28+1,AG28,"") -> 5 | AT28: =IF(AH28<AC28+1,AH28,"") -> 6 | AU28: =IF(AI28<AC28+1,AI28,"") -> 7 | AV28: =IF(AJ28<AC28+1,AJ28,"") | AW28: =IF(AK28<AC28+1,AK28,"") | AX28: =IF(AL28<AC28+1,AL28,"") | AY28: =IF(AM28<AC28+1,AM28,"") | AZ28: =IF(AN28<AC28+1,AN28,"") | BA28: =IF(AO28<AC28+1,AO28,"") | BB28: =IF(AP28<AC28+1,AP28,"") | BC28: =IF(AQ28<AC28+1,AQ28,"") | BD28: =S28&AR28&AD28 -> Subbagian Perencanaan Evaluasi dan Pelaporan42026 | BE28: =S28&AS28&AD28 -> Subbagian Perencanaan Evaluasi dan Pelaporan52026 | BF28: =S28&AT28&AD28 -> Subbagian Perencanaan Evaluasi dan Pelaporan62026 | BG28: =S28&AU28&AD28 -> Subbagian Perencanaan Evaluasi dan Pelaporan72026 | BH28: =S28&AV28&AD28 -> Subbagian Perencanaan Evaluasi dan Pelaporan2026 | BI28: =S28&AW28&AD28 -> Subbagian Perencanaan Evaluasi dan Pelaporan2026 | BJ28: =S28&AX28&AD28 -> Subbagian Perencanaan Evaluasi dan Pelaporan2026 | BK28: =S28&AY28&AD28 -> Subbagian Perencanaan Evaluasi dan Pelaporan2026 | BL28: =S28&AZ28&AD28 -> Subbagian Perencanaan Evaluasi dan Pelaporan2026 | BM28: =S28&BA28&AD28 -> Subbagian Perencanaan Evaluasi dan Pelaporan2026 | BN28: =S28&BB28&AD28 -> Subbagian Perencanaan Evaluasi dan Pelaporan2026 | BO28: =S28&BC28&AD28 -> Subbagian Perencanaan Evaluasi dan Pelaporan2026
B29: 6694 | C29: 6695 | E29: 14 | F29: April | G29: 2026 | H29: =VLOOKUP(F29,MASTER!$B$2:$C$13,2,FALSE) -> IV | I29: Praktek Kerja Lapangan | J29: 400.145.4/0738/Diskominfo/2026 | K29: 27 Maret 2026 | L29: Sekretaris Daerah | M29: Praktek Kerja Lapangan | N29: Kepala Program Studi Teknik Informatika Universitas Bina Darma Palembang | O29: Ferdy Pratama | P29: 231420077 | Q29: NIM | R29: Program Studi Teknik Informatika | S29: Subbagian Perencanaan Evaluasi dan Pelaporan | T29: =IF(Q29="NIM","Mahasiswa","Peserta Didik") -> Mahasiswa | U29: Universitas Bina Darma Palembang | V29: 14 April 2026 | W29: 14 Juli 2026 | X29: Kepala Dinas Kominfo Provinsi Sumatera Selatan | Y29: Kepala Program Studi Teknik Informatika Universitas Bina Darma Palembang | AA29: =IF(ISNA(MATCH(O29,SERTIFIKAT!$G$2:$G$237,0)),"","SERTIFIKAT SELESAI") | AB29: =MONTH(V29) -> 4 | AC29: =MONTH(W29) -> 7 | AD29: =YEAR(V29) -> 2026 | AE29: =YEAR(W29) -> 2026 | AF29: =AB29 -> 4 | AG29: =AF29+1 -> 5 | AH29: =AG29+1 -> 6 | AI29: =AH29+1 -> 7 | AJ29: =AI29+1 -> 8 | AK29: =AJ29+1 -> 9 | AL29: =AK29+1 -> 10 | AM29: =AL29+1 -> 11 | AN29: =AM29+1 -> 12 | ... AQ29: =AP29+1 -> 15 | AR29: =IF(AF29<AC29+1,AF29,"") -> 4 | AS29: =IF(AG29<AC29+1,AG29,"") -> 5 | AT29: =IF(AH29<AC29+1,AH29,"") -> 6 | AU29: =IF(AI29<AC29+1,AI29,"") -> 7 | AV29: =IF(AJ29<AC29+1,AJ29,"") | AW29: =IF(AK29<AC29+1,AK29,"") | AX29: =IF(AL29<AC29+1,AL29,"") | AY29: =IF(AM29<AC29+1,AM29,"") | AZ29: =IF(AN29<AC29+1,AN29,"") | BA29: =IF(AO29<AC29+1,AO29,"") | BB29: =IF(AP29<AC29+1,AP29,"") | BC29: =IF(AQ29<AC29+1,AQ29,"") | BD29: =S29&AR29&AD29 -> Subbagian Perencanaan Evaluasi dan Pelaporan42026 | BE29: =S29&AS29&AD29 -> Subbagian Perencanaan Evaluasi dan Pelaporan52026 | BF29: =S29&AT29&AD29 -> Subbagian Perencanaan Evaluasi dan Pelaporan62026 | BG29: =S29&AU29&AD29 -> Subbagian Perencanaan Evaluasi dan Pelaporan72026 | BH29: =S29&AV29&AD29 -> Subbagian Perencanaan Evaluasi dan Pelaporan2026 | BI29: =S29&AW29&AD29 -> Subbagian Perencanaan Evaluasi dan Pelaporan2026 | BJ29: =S29&AX29&AD29 -> Subbagian Perencanaan Evaluasi dan Pelaporan2026 | BK29: =S29&AY29&AD29 -> Subbagian Perencanaan Evaluasi dan Pelaporan2026 | BL29: =S29&AZ29&AD29 -> Subbagian Perencanaan Evaluasi dan Pelaporan2026 | BM29: =S29&BA29&AD29 -> Subbagian Perencanaan Evaluasi dan Pelaporan2026 | BN29: =S29&BB29&AD29 -> Subbagian Perencanaan Evaluasi dan Pelaporan2026 | BO29: =S29&BC29&AD29 -> Subbagian Perencanaan Evaluasi dan Pelaporan2026
B30: 6735 | C30: 6736 | E30: 14 | F30: April | G30: 2026 | H30: =VLOOKUP(F30,MASTER!$B$2:$C$13,2,FALSE) -> IV | I30: Surat Permohonan Praktek Kerja Industri | J30: 552/BKK/PRAKERIN/SMK.B/II/2026 | K30: 01 April 2026 | L30: Kepala SMK Bistek Palembang | M30: Praktek Kerja Industri | N30: Kepala SMK Bistek Palembang | O30: Putri Anggraini | P30: 0096319461 | Q30: NIS/NISN | R30: Otomatisasi Tata Kelola Perkantoran | S30: Subbagian Umum dan Kepegawaian | T30: =IF(Q30="NIM","Mahasiswa","Peserta Didik") -> Peserta Didik | U30: SMK Bistek Palembang | V30: 01 Juli 2026 | W30: 30 September 2026 | X30: Kepala SMK Bistek Palembang | AA30: =IF(ISNA(MATCH(O30,SERTIFIKAT!$G$2:$G$237,0)),"","SERTIFIKAT SELESAI") | AB30: =MONTH(V30) -> 7 | AC30: =MONTH(W30) -> 9 | AD30: =YEAR(V30) -> 2026 | AE30: =YEAR(W30) -> 2026 | AF30: =AB30 -> 7 | AG30: =AF30+1 -> 8 | AH30: =AG30+1 -> 9 | AI30: =AH30+1 -> 10 | AJ30: =AI30+1 -> 11 | AK30: =AJ30+1 -> 12 | AL30: =AK30+1 -> 13 | AM30: =AL30+1 -> 14 | AN30: =AM30+1 -> 15 | ... AQ30: =AP30+1 -> 18 | AR30: =IF(AF30<AC30+1,AF30,"") -> 7 | AS30: =IF(AG30<AC30+1,AG30,"") -> 8 | AT30: =IF(AH30<AC30+1,AH30,"") -> 9 | AU30: =IF(AI30<AC30+1,AI30,"") | AV30: =IF(AJ30<AC30+1,AJ30,"") | AW30: =IF(AK30<AC30+1,AK30,"") | AX30: =IF(AL30<AC30+1,AL30,"") | AY30: =IF(AM30<AC30+1,AM30,"") | AZ30: =IF(AN30<AC30+1,AN30,"") | BA30: =IF(AO30<AC30+1,AO30,"") | BB30: =IF(AP30<AC30+1,AP30,"") | BC30: =IF(AQ30<AC30+1,AQ30,"") | BD30: =S30&AR30&AD30 -> Subbagian Umum dan Kepegawaian72026 | BE30: =S30&AS30&AD30 -> Subbagian Umum dan Kepegawaian82026 | BF30: =S30&AT30&AD30 -> Subbagian Umum dan Kepegawaian92026 | BG30: =S30&AU30&AD30 -> Subbagian Umum dan Kepegawaian2026 | BH30: =S30&AV30&AD30 -> Subbagian Umum dan Kepegawaian2026 | BI30: =S30&AW30&AD30 -> Subbagian Umum dan Kepegawaian2026 | BJ30: =S30&AX30&AD30 -> Subbagian Umum dan Kepegawaian2026 | BK30: =S30&AY30&AD30 -> Subbagian Umum dan Kepegawaian2026 | BL30: =S30&AZ30&AD30 -> Subbagian Umum dan Kepegawaian2026 | BM30: =S30&BA30&AD30 -> Subbagian Umum dan Kepegawaian2026 | BN30: =S30&BB30&AD30 -> Subbagian Umum dan Kepegawaian2026 | BO30: =S30&BC30&AD30 -> Subbagian Umum dan Kepegawaian2026
B31: 6735 | C31: 6736 | E31: 14 | F31: April | G31: 2026 | H31: =VLOOKUP(F31,MASTER!$B$2:$C$13,2,FALSE) -> IV | I31: Surat Permohonan Praktek Kerja Industri | J31: 552/BKK/PRAKERIN/SMK.B/II/2026 | K31: 01 April 2026 | L31: Kepala SMK Bistek Palembang | M31: Praktek Kerja Industri | N31: Kepala SMK Bistek Palembang | O31: Nadila Brilian | P31: 0083073689 | Q31: NIS/NISN | R31: Otomatisasi Tata Kelola Perkantoran | S31: Subbagian Umum dan Kepegawaian | T31: =IF(Q31="NIM","Mahasiswa","Peserta Didik") -> Peserta Didik | U31: SMK Bistek Palembang | V31: 01 Juli 2026 | W31: 30 September 2026 | X31: Kepala SMK Bistek Palembang | AA31: =IF(ISNA(MATCH(O31,SERTIFIKAT!$G$2:$G$237,0)),"","SERTIFIKAT SELESAI") | AB31: =MONTH(V31) -> 7 | AC31: =MONTH(W31) -> 9 | AD31: =YEAR(V31) -> 2026 | AE31: =YEAR(W31) -> 2026 | AF31: =AB31 -> 7 | AG31: =AF31+1 -> 8 | AH31: =AG31+1 -> 9 | AI31: =AH31+1 -> 10 | AJ31: =AI31+1 -> 11 | AK31: =AJ31+1 -> 12 | AL31: =AK31+1 -> 13 | AM31: =AL31+1 -> 14 | AN31: =AM31+1 -> 15 | ... AQ31: =AP31+1 -> 18 | AR31: =IF(AF31<AC31+1,AF31,"") -> 7 | AS31: =IF(AG31<AC31+1,AG31,"") -> 8 | AT31: =IF(AH31<AC31+1,AH31,"") -> 9 | AU31: =IF(AI31<AC31+1,AI31,"") | AV31: =IF(AJ31<AC31+1,AJ31,"") | AW31: =IF(AK31<AC31+1,AK31,"") | AX31: =IF(AL31<AC31+1,AL31,"") | AY31: =IF(AM31<AC31+1,AM31,"") | AZ31: =IF(AN31<AC31+1,AN31,"") | BA31: =IF(AO31<AC31+1,AO31,"") | BB31: =IF(AP31<AC31+1,AP31,"") | BC31: =IF(AQ31<AC31+1,AQ31,"") | BD31: =S31&AR31&AD31 -> Subbagian Umum dan Kepegawaian72026 | BE31: =S31&AS31&AD31 -> Subbagian Umum dan Kepegawaian82026 | BF31: =S31&AT31&AD31 -> Subbagian Umum dan Kepegawaian92026 | BG31: =S31&AU31&AD31 -> Subbagian Umum dan Kepegawaian2026 | BH31: =S31&AV31&AD31 -> Subbagian Umum dan Kepegawaian2026 | BI31: =S31&AW31&AD31 -> Subbagian Umum dan Kepegawaian2026 | BJ31: =S31&AX31&AD31 -> Subbagian Umum dan Kepegawaian2026 | BK31: =S31&AY31&AD31 -> Subbagian Umum dan Kepegawaian2026 | BL31: =S31&AZ31&AD31 -> Subbagian Umum dan Kepegawaian2026 | BM31: =S31&BA31&AD31 -> Subbagian Umum dan Kepegawaian2026 | BN31: =S31&BB31&AD31 -> Subbagian Umum dan Kepegawaian2026 | BO31: =S31&BC31&AD31 -> Subbagian Umum dan Kepegawaian2026
H32: =VLOOKUP(F32,MASTER!$B$2:$C$13,2,FALSE) -> #N/A | I32: Praktek Kerja Lapangan | J32: 420/4454/Set.3-Disdik.SS/II/2026 | K32: 19 Februari 2026 | L32: Kepala SMK Bina Jaya Palembang | M32: Praktek Kerja Lapangan | N32: Kepala SMK Bina Jaya Palembang | O32: Muhammad Ilham | P32: 13.089 | Q32: NIS/NISN | R32: Manajemen Perkantoran | S32: Subbagian Umum dan Kepegawaian | T32: =IF(Q32="NIM","Mahasiswa","Peserta Didik") -> Peserta Didik | U32: SMK Bina Jaya Palembang | V32: 16 Juli 2026 | W32: 15 Januari 2027 | X32: Kepala SMK Bina Jaya Palembang | AB32: =MONTH(V32) -> 7 | AC32: =MONTH(W32) -> 1 | AD32: =YEAR(V32) -> 2026 | AE32: =YEAR(W32) -> 2027 | AF32: =AB32 -> 7 | AG32: =AF32+1 -> 8 | AH32: =AG32+1 -> 9 | AI32: =AH32+1 -> 10 | AJ32: =AI32+1 -> 11 | AK32: =AJ32+1 -> 12 | AL32: =AK32+1 -> 13 | AM32: =AL32+1 -> 14 | AN32: =AM32+1 -> 15 | ... AQ32: =AP32+1 -> 18 | AR32: 7 | AS32: 8 | AT32: 9 | AU32: 10 | AV32: 11 | AW32: 12 | AX32: =IF(AL32<AC32+1,AL32,"") | AY32: =IF(AM32<AC32+1,AM32,"") | AZ32: =IF(AN32<AC32+1,AN32,"") | BA32: =IF(AO32<AC32+1,AO32,"") | BB32: =IF(AP32<AC32+1,AP32,"") | BC32: =IF(AQ32<AC32+1,AQ32,"") | BD32: =S32&AR32&AD32 -> Subbagian Umum dan Kepegawaian72026 | BE32: =S32&AS32&AD32 -> Subbagian Umum dan Kepegawaian82026 | BF32: =S32&AT32&AD32 -> Subbagian Umum dan Kepegawaian92026 | BG32: =S32&AU32&AD32 -> Subbagian Umum dan Kepegawaian102026 | BH32: =S32&AV32&AD32 -> Subbagian Umum dan Kepegawaian112026 | BI32: =S32&AW32&AD32 -> Subbagian Umum dan Kepegawaian122026 | BJ32: =S32&AX32&AD32 -> Subbagian Umum dan Kepegawaian2026 | BK32: =S32&AY32&AD32 -> Subbagian Umum dan Kepegawaian2026 | BL32: =S32&AZ32&AD32 -> Subbagian Umum dan Kepegawaian2026 | BM32: =S32&BA32&AD32 -> Subbagian Umum dan Kepegawaian2026 | BN32: =S32&BB32&AD32 -> Subbagian Umum dan Kepegawaian2026 | BO32: =S32&BC32&AD32 -> Subbagian Umum dan Kepegawaian2026
H33: =VLOOKUP(F33,MASTER!$B$2:$C$13,2,FALSE) -> #N/A | O33: Annisa Nur Safira | P33: 14.116 | Q33: NIS/NISN | R33: Manajemen Perkantoran | S33: Subbagian Umum dan Kepegawaian | T33: =IF(Q33="NIM","Mahasiswa","Peserta Didik") -> Peserta Didik | U33: SMK Bina Jaya Palembang | V33: 16 Juli 2026 | W33: 15 Januari 2027 | X33: Kepala SMK Bina Jaya Palembang | AB33: =MONTH(V33) -> 7 | AC33: =MONTH(W33) -> 1 | AD33: =YEAR(V33) -> 2026 | AE33: =YEAR(W33) -> 2027 | AF33: =AB33 -> 7 | AG33: =AF33+1 -> 8 | AH33: =AG33+1 -> 9 | AI33: =AH33+1 -> 10 | AJ33: =AI33+1 -> 11 | AK33: =AJ33+1 -> 12 | AL33: =AK33+1 -> 13 | AM33: =AL33+1 -> 14 | AN33: =AM33+1 -> 15 | ... AQ33: =AP33+1 -> 18 | AR33: 7 | AS33: 8 | AT33: 9 | AU33: 10 | AV33: 11 | AW33: 12 | AY33: =IF(AM33<AC33+1,AM33,"") | AZ33: =IF(AN33<AC33+1,AN33,"") | BA33: =IF(AO33<AC33+1,AO33,"") | BB33: =IF(AP33<AC33+1,AP33,"") | BC33: =IF(AQ33<AC33+1,AQ33,"") | BD33: =S33&AR33&AD33 -> Subbagian Umum dan Kepegawaian72026 | BE33: =S33&AS33&AD33 -> Subbagian Umum dan Kepegawaian82026 | BF33: =S33&AT33&AD33 -> Subbagian Umum dan Kepegawaian92026 | BG33: =S33&AU33&AD33 -> Subbagian Umum dan Kepegawaian102026 | BH33: =S33&AV33&AD33 -> Subbagian Umum dan Kepegawaian112026 | BI33: =S33&AW33&AD33 -> Subbagian Umum dan Kepegawaian122026 | BJ33: =S33&AX33&AD33 -> Subbagian Umum dan Kepegawaian2026 | BK33: =S33&AY33&AD33 -> Subbagian Umum dan Kepegawaian2026 | BL33: =S33&AZ33&AD33 -> Subbagian Umum dan Kepegawaian2026 | BM33: =S33&BA33&AD33 -> Subbagian Umum dan Kepegawaian2026 | BN33: =S33&BB33&AD33 -> Subbagian Umum dan Kepegawaian2026 | BO33: =S33&BC33&AD33 -> Subbagian Umum dan Kepegawaian2026
H34: =VLOOKUP(F34,MASTER!$B$2:$C$13,2,FALSE) -> #N/A | O34: Nadia Alaika | P34: 14.094 | Q34: NIS/NISN | R34: Manajemen Perkantoran | S34: Seksi PTK SMK | T34: =IF(Q34="NIM","Mahasiswa","Peserta Didik") -> Peserta Didik | U34: SMK Bina Jaya Palembang | V34: 16 Juli 2026 | W34: 15 Januari 2027 | X34: Kepala SMK Bina Jaya Palembang | AB34: =MONTH(V34) -> 7 | AC34: =MONTH(W34) -> 1 | AD34: =YEAR(V34) -> 2026 | AE34: =YEAR(W34) -> 2027 | AF34: =AB34 -> 7 | AG34: =AF34+1 -> 8 | AH34: =AG34+1 -> 9 | AI34: =AH34+1 -> 10 | AJ34: =AI34+1 -> 11 | AK34: =AJ34+1 -> 12 | AL34: =AK34+1 -> 13 | AM34: =AL34+1 -> 14 | AN34: =AM34+1 -> 15 | ... AQ34: =AP34+1 -> 18 | AR34: 7 | AS34: 8 | AT34: 9 | AU34: 10 | AV34: 11 | AW34: 12 | AY34: =IF(AM34<AC34+1,AM34,"") | AZ34: =IF(AN34<AC34+1,AN34,"") | BA34: =IF(AO34<AC34+1,AO34,"") | BB34: =IF(AP34<AC34+1,AP34,"") | BC34: =IF(AQ34<AC34+1,AQ34,"") | BD34: =S34&AR34&AD34 -> Seksi PTK SMK72026 | BE34: =S34&AS34&AD34 -> Seksi PTK SMK82026 | BF34: =S34&AT34&AD34 -> Seksi PTK SMK92026 | BG34: =S34&AU34&AD34 -> Seksi PTK SMK102026 | BH34: =S34&AV34&AD34 -> Seksi PTK SMK112026 | BI34: =S34&AW34&AD34 -> Seksi PTK SMK122026 | BJ34: =S34&AX34&AD34 -> Seksi PTK SMK2026 | BK34: =S34&AY34&AD34 -> Seksi PTK SMK2026 | BL34: =S34&AZ34&AD34 -> Seksi PTK SMK2026 | BM34: =S34&BA34&AD34 -> Seksi PTK SMK2026 | BN34: =S34&BB34&AD34 -> Seksi PTK SMK2026 | BO34: =S34&BC34&AD34 -> Seksi PTK SMK2026
H35: =VLOOKUP(F35,MASTER!$B$2:$C$13,2,FALSE) -> #N/A | O35: Rizkah Aulia Khoirunnisa | P35: 14.151 | Q35: NIS/NISN | R35: Manajemen Perkantoran | S35: Seksi PTK SMA | T35: =IF(Q35="NIM","Mahasiswa","Peserta Didik") -> Peserta Didik | U35: SMK Bina Jaya Palembang | V35: 16 Juli 2026 | W35: 15 Januari 2027 | X35: Kepala SMK Bina Jaya Palembang | AB35: =MONTH(V35) -> 7 | AC35: =MONTH(W35) -> 1 | AD35: =YEAR(V35) -> 2026 | AE35: =YEAR(W35) -> 2027 | AF35: =AB35 -> 7 | AG35: =AF35+1 -> 8 | AH35: =AG35+1 -> 9 | AI35: =AH35+1 -> 10 | AJ35: =AI35+1 -> 11 | AK35: =AJ35+1 -> 12 | AL35: =AK35+1 -> 13 | AM35: =AL35+1 -> 14 | AN35: =AM35+1 -> 15 | ... AQ35: =AP35+1 -> 18 | AR35: 7 | AS35: 8 | AT35: 9 | AU35: 10 | AV35: 11 | AW35: 12 | AY35: =IF(AM35<AC35+1,AM35,"") | AZ35: =IF(AN35<AC35+1,AN35,"") | BA35: =IF(AO35<AC35+1,AO35,"") | BB35: =IF(AP35<AC35+1,AP35,"") | BC35: =IF(AQ35<AC35+1,AQ35,"") | BD35: =S35&AR35&AD35 -> Seksi PTK SMA72026 | BE35: =S35&AS35&AD35 -> Seksi PTK SMA82026 | BF35: =S35&AT35&AD35 -> Seksi PTK SMA92026 | BG35: =S35&AU35&AD35 -> Seksi PTK SMA102026 | BH35: =S35&AV35&AD35 -> Seksi PTK SMA112026 | BI35: =S35&AW35&AD35 -> Seksi PTK SMA122026 | BJ35: =S35&AX35&AD35 -> Seksi PTK SMA2026 | BK35: =S35&AY35&AD35 -> Seksi PTK SMA2026 | BL35: =S35&AZ35&AD35 -> Seksi PTK SMA2026 | BM35: =S35&BA35&AD35 -> Seksi PTK SMA2026 | BN35: =S35&BB35&AD35 -> Seksi PTK SMA2026 | BO35: =S35&BC35&AD35 -> Seksi PTK SMA2026
B36: 7143 | C36: 7144 | E36: 23 | F36: April | G36: 2026 | H36: =VLOOKUP(F36,MASTER!$B$2:$C$13,2,FALSE) -> IV | I36: Permohonan Pelaksanaan Pendidikan Sistem Ganda (PSG) Kelas XI SMK Pembina 1 Palembang | J36: 028/SMK.YP/E.11/IV/2026 | K36: 14 April 2026 | L36: Kepala SMK Pembina 1 Palembang | M36: Praktek Kerja Lapangan | N36: Kepala SMK Pembina 1 Palembang | O36: Yuhanis Apriani | P36: 08217 | Q36: NIS/NISN | R36: Manajemen Perkantoran dan Layanan Bisnis | S36: Seksi Kurikulum SMA | T36: =IF(Q36="NIM","Mahasiswa","Peserta Didik") -> Peserta Didik | U36: SMK Pembina 1 Palembang | V36: 06 Juli 2026 | W36: 28 November 2026 | X36: SMK Pembina 1 Palembang | AA36: =IF(ISNA(MATCH(O36,SERTIFIKAT!$G$2:$G$237,0)),"","SERTIFIKAT SELESAI") | AB36: =MONTH(V36) -> 7 | AC36: =MONTH(W36) -> 11 | AD36: =YEAR(V36) -> 2026 | AE36: =YEAR(W36) -> 2026 | AF36: =AB36 -> 7 | AG36: =AF36+1 -> 8 | AH36: =AG36+1 -> 9 | AI36: =AH36+1 -> 10 | AJ36: =AI36+1 -> 11 | AK36: =AJ36+1 -> 12 | AL36: =AK36+1 -> 13 | AM36: =AL36+1 -> 14 | AN36: =AM36+1 -> 15 | ... AQ36: =AP36+1 -> 18 | AR36: =IF(AF36<AC36+1,AF36,"") -> 7 | AS36: =IF(AG36<AC36+1,AG36,"") -> 8 | AT36: =IF(AH36<AC36+1,AH36,"") -> 9 | AU36: =IF(AI36<AC36+1,AI36,"") -> 10 | AV36: =IF(AJ36<AC36+1,AJ36,"") -> 11 | AW36: =IF(AK36<AC36+1,AK36,"") | AX36: =IF(AL36<AC36+1,AL36,"") | AY36: =IF(AM36<AC36+1,AM36,"") | AZ36: =IF(AN36<AC36+1,AN36,"") | BA36: =IF(AO36<AC36+1,AO36,"") | BB36: =IF(AP36<AC36+1,AP36,"") | BC36: =IF(AQ36<AC36+1,AQ36,"") | BD36: =S36&AR36&AD36 -> Seksi Kurikulum SMA72026 | BE36: =S36&AS36&AD36 -> Seksi Kurikulum SMA82026 | BF36: =S36&AT36&AD36 -> Seksi Kurikulum SMA92026 | BG36: =S36&AU36&AD36 -> Seksi Kurikulum SMA102026 | BH36: =S36&AV36&AD36 -> Seksi Kurikulum SMA112026 | BI36: =S36&AW36&AD36 -> Seksi Kurikulum SMA2026 | BJ36: =S36&AX36&AD36 -> Seksi Kurikulum SMA2026 | BK36: =S36&AY36&AD36 -> Seksi Kurikulum SMA2026 | BL36: =S36&AZ36&AD36 -> Seksi Kurikulum SMA2026 | BM36: =S36&BA36&AD36 -> Seksi Kurikulum SMA2026 | BN36: =S36&BB36&AD36 -> Seksi Kurikulum SMA2026 | BO36: =S36&BC36&AD36 -> Seksi Kurikulum SMA2026
